<?xml version="1.0" ?>
<!-- =================================================================================== -->
<!-- |    This document was autogenerated by xacro from model.xacro                    | -->
<!-- |    EDITING THIS FILE BY HAND IS NOT RECOMMENDED                                 | -->
<!-- =================================================================================== -->
<robot name="tether">
  <!-- Xacro to generate tether SDF -->
  <!-- Note: need to manually find and replace all references to 'continuous'
    with 'ball' in final SDF to get better tether-->
  <link name="element_1">
    <inertial>
      <origin rpy="0 1.5707963267948966 0" xyz="0.75 0 0"/>
      <mass value="0.1"/>
      <inertia ixx="0.018752500000000002" ixy="0" ixz="0" iyy="0.018752500000000002" iyz="0" izz="5e-06"/>
    </inertial>
    <visual>
      <origin rpy="0 1.5707963267948966 0" xyz="0.75 0 0"/>
      <geometry>
        <cylinder length="1.5" radius="0.01"/>
      </geometry>
    </visual>
    <collision>
      <origin rpy="0 1.5707963267948966 0" xyz="0.75 0 0"/>
      <geometry>
        <!-- <cylinder length="${elem_length}" radius="${tether_radius}"/> -->
        <cylinder length="0.0001" radius="0.0001"/>
      </geometry>
      <!-- <surface>
                    <contact>
                        <collide_without_contact>true</collide_without_contact>
                    </contact>
                </surface> -->
    </collision>
  </link>
  <link name="element_0">
    <inertial>
      <origin rpy="0 1.5707963267948966 0" xyz="0.005 0 0"/>
      <mass value="0.0006666666666666668"/>
      <inertia ixx="2.2222222222222224e-08" ixy="0" ixz="0" iyy="2.2222222222222224e-08" iyz="0" izz="3.333333333333334e-08"/>
    </inertial>
    <visual>
      <origin rpy="0 1.5707963267948966 0" xyz="0.005 0 0"/>
      <geometry>
        <cylinder length="0.01" radius="0.01"/>
      </geometry>
    </visual>
    <collision>
      <origin rpy="0 1.5707963267948966 0" xyz="0.005 0 0"/>
      <geometry>
        <!-- <cylinder length="${elem_length}" radius="${tether_radius}"/> -->
        <cylinder length="0.0001" radius="0.0001"/>
      </geometry>
      <!-- <surface>
                    <contact>
                        <collide_without_contact>true</collide_without_contact>
                    </contact>
                </surface> -->
    </collision>
  </link>
  <link name="element_2">
    <inertial>
      <origin rpy="0 1.5707963267948966 0" xyz="0.005 0 0"/>
      <mass value="0.0006666666666666668"/>
      <inertia ixx="2.2222222222222224e-08" ixy="0" ixz="0" iyy="2.2222222222222224e-08" iyz="0" izz="3.333333333333334e-08"/>
    </inertial>
    <visual>
      <origin rpy="0 1.5707963267948966 0" xyz="0.005 0 0"/>
      <geometry>
        <cylinder length="0.01" radius="0.01"/>
      </geometry>
    </visual>
    <collision>
      <origin rpy="0 1.5707963267948966 0" xyz="0.005 0 0"/>
      <geometry>
        <!-- <cylinder length="${elem_length}" radius="${tether_radius}"/> -->
        <cylinder length="0.0001" radius="0.0001"/>
      </geometry>
      <!-- <surface>
                    <contact>
                        <collide_without_contact>true</collide_without_contact>
                    </contact>
                </surface> -->
    </collision>
  </link>
  <joint name="joint_0_to_1" type="continuous">
    <axis xyz="0. 1. 1."/>
    <origin rpy="0 0 0" xyz="0.01 0 0"/>
    <parent link="element_0"/>
    <child link="element_1"/>
  </joint>
  <joint name="joint_1_to_2" type="continuous">
    <axis xyz="0. 1. 1."/>
    <origin rpy="0 0 0" xyz="1.5 0 0"/>
    <parent link="element_1"/>
    <child link="element_2"/>
  </joint>
  <!-- Define joints -->
  <!-- Add start element joint-->
  <!-- <xacro:if value="${elem_num-1 == 0}">
            <joint name="joint_${elem_num-1}_to_${elem_num}" type="fixed">
                <axis xyz="0. 0. 1."/>
                <origin xyz="${elem_length} 0 0" rpy="0 0 0"/>
                <parent link="element_${elem_num-1}"/>
                <child link="element_${elem_num}"/>
            </joint>
        </xacro:if> -->
</robot>
