<sdf version='1.10'>
  <model name='tether'>
    <link name='element_0'>
      <inertial>
        <pose>0.0050000000000000001 0 0 0 1.5707963267948966 0</pose>
        <mass>0.00066666666666666664</mass>
        <inertia>
          <ixx>2.222222222222222e-08</ixx>
          <ixy>0</ixy>
          <ixz>0</ixz>
          <iyy>2.222222222222222e-08</iyy>
          <iyz>0</iyz>
          <izz>3.3333333333333327e-08</izz>
        </inertia>
      </inertial>
      <collision name='element_0_collision'>
        <pose>0.0050000000000000001 0 0 0 1.5707963267948966 0</pose>
        <geometry>
          <cylinder>
            <length>0.0001</length>
            <radius>0.0001</radius>
          </cylinder>
        </geometry>
      </collision>
      <visual name='element_0_visual'>
        <pose>0.0050000000000000001 0 0 0 1.5707963267948966 0</pose>
        <geometry>
          <cylinder>
            <length>0.01</length>
            <radius>0.01</radius>
          </cylinder>
        </geometry>
      </visual>
    </link>
    <joint name='joint_0_to_1' type='ball'>
      <pose relative_to='element_0'>0.01 0 0 0 0 0</pose>
      <parent>element_0</parent>
      <child>element_1</child>
      <axis>
        <xyz>0 1 1</xyz>
        <limit>
          <lower>-inf</lower>
          <upper>inf</upper>
        </limit>
        <dynamics>
          <spring_reference>0</spring_reference>
          <spring_stiffness>0</spring_stiffness>
        </dynamics>
      </axis>
    </joint>
    <link name='element_1'>
      <pose relative_to='joint_0_to_1'>0 0 0 0 0 0</pose>
      <inertial>
        <pose>0.074999999999999997 0 0 0 1.5707963267948966 0</pose>
        <mass>0.01</mass>
        <inertia>
          <ixx>1.9000000000000001e-05</ixx>
          <ixy>0</ixy>
          <ixz>0</ixz>
          <iyy>1.9000000000000001e-05</iyy>
          <iyz>0</iyz>
          <izz>5.0000000000000008e-07</izz>
        </inertia>
      </inertial>
      <collision name='element_1_collision'>
        <pose>0.074999999999999997 0 0 0 1.5707963267948966 0</pose>
        <geometry>
          <cylinder>
            <length>0.0001</length>
            <radius>0.0001</radius>
          </cylinder>
        </geometry>
      </collision>
      <visual name='element_1_visual'>
        <pose>0.074999999999999997 0 0 0 1.5707963267948966 0</pose>
        <geometry>
          <cylinder>
            <length>0.14999999999999999</length>
            <radius>0.01</radius>
          </cylinder>
        </geometry>
      </visual>
    </link>
    <joint name='joint_1_to_2' type='ball'>
      <pose relative_to='element_1'>0.14999999999999999 0 0 0 0 0</pose>
      <parent>element_1</parent>
      <child>element_2</child>
      <axis>
        <xyz>0 1 1</xyz>
        <limit>
          <lower>-inf</lower>
          <upper>inf</upper>
        </limit>
        <dynamics>
          <damping>10</damping>
          <friction>0</friction>
          <spring_reference>0</spring_reference>
          <spring_stiffness>0</spring_stiffness>
        </dynamics>
      </axis>
    </joint>
    <link name='element_2'>
      <pose relative_to='joint_1_to_2'>0 0 0 0 0 0</pose>
      <inertial>
        <pose>0.074999999999999997 0 0 0 1.5707963267948966 0</pose>
        <mass>0.01</mass>
        <inertia>
          <ixx>1.9000000000000001e-05</ixx>
          <ixy>0</ixy>
          <ixz>0</ixz>
          <iyy>1.9000000000000001e-05</iyy>
          <iyz>0</iyz>
          <izz>5.0000000000000008e-07</izz>
        </inertia>
      </inertial>
      <collision name='element_2_collision'>
        <pose>0.074999999999999997 0 0 0 1.5707963267948966 0</pose>
        <geometry>
          <cylinder>
            <length>0.0001</length>
            <radius>0.0001</radius>
          </cylinder>
        </geometry>
      </collision>
      <visual name='element_2_visual'>
        <pose>0.074999999999999997 0 0 0 1.5707963267948966 0</pose>
        <geometry>
          <cylinder>
            <length>0.14999999999999999</length>
            <radius>0.01</radius>
          </cylinder>
        </geometry>
      </visual>
    </link>
    <joint name='joint_2_to_3' type='ball'>
      <pose relative_to='element_2'>0.14999999999999999 0 0 0 0 0</pose>
      <parent>element_2</parent>
      <child>element_3</child>
      <axis>
        <xyz>0 1 1</xyz>
        <limit>
          <lower>-inf</lower>
          <upper>inf</upper>
        </limit>
        <dynamics>
          <damping>10</damping>
          <friction>0</friction>
          <spring_reference>0</spring_reference>
          <spring_stiffness>0</spring_stiffness>
        </dynamics>
      </axis>
    </joint>
    <link name='element_3'>
      <pose relative_to='joint_2_to_3'>0 0 0 0 0 0</pose>
      <inertial>
        <pose>0.074999999999999997 0 0 0 1.5707963267948966 0</pose>
        <mass>0.01</mass>
        <inertia>
          <ixx>1.9000000000000001e-05</ixx>
          <ixy>0</ixy>
          <ixz>0</ixz>
          <iyy>1.9000000000000001e-05</iyy>
          <iyz>0</iyz>
          <izz>5.0000000000000008e-07</izz>
        </inertia>
      </inertial>
      <collision name='element_3_collision'>
        <pose>0.074999999999999997 0 0 0 1.5707963267948966 0</pose>
        <geometry>
          <cylinder>
            <length>0.0001</length>
            <radius>0.0001</radius>
          </cylinder>
        </geometry>
      </collision>
      <visual name='element_3_visual'>
        <pose>0.074999999999999997 0 0 0 1.5707963267948966 0</pose>
        <geometry>
          <cylinder>
            <length>0.14999999999999999</length>
            <radius>0.01</radius>
          </cylinder>
        </geometry>
      </visual>
    </link>
    <joint name='joint_3_to_4' type='ball'>
      <pose relative_to='element_3'>0.14999999999999999 0 0 0 0 0</pose>
      <parent>element_3</parent>
      <child>element_4</child>
      <axis>
        <xyz>0 1 1</xyz>
        <limit>
          <lower>-inf</lower>
          <upper>inf</upper>
        </limit>
        <dynamics>
          <damping>10</damping>
          <friction>0</friction>
          <spring_reference>0</spring_reference>
          <spring_stiffness>0</spring_stiffness>
        </dynamics>
      </axis>
    </joint>
    <link name='element_4'>
      <pose relative_to='joint_3_to_4'>0 0 0 0 0 0</pose>
      <inertial>
        <pose>0.074999999999999997 0 0 0 1.5707963267948966 0</pose>
        <mass>0.01</mass>
        <inertia>
          <ixx>1.9000000000000001e-05</ixx>
          <ixy>0</ixy>
          <ixz>0</ixz>
          <iyy>1.9000000000000001e-05</iyy>
          <iyz>0</iyz>
          <izz>5.0000000000000008e-07</izz>
        </inertia>
      </inertial>
      <collision name='element_4_collision'>
        <pose>0.074999999999999997 0 0 0 1.5707963267948966 0</pose>
        <geometry>
          <cylinder>
            <length>0.0001</length>
            <radius>0.0001</radius>
          </cylinder>
        </geometry>
      </collision>
      <visual name='element_4_visual'>
        <pose>0.074999999999999997 0 0 0 1.5707963267948966 0</pose>
        <geometry>
          <cylinder>
            <length>0.14999999999999999</length>
            <radius>0.01</radius>
          </cylinder>
        </geometry>
      </visual>
    </link>
    <joint name='joint_4_to_5' type='ball'>
      <pose relative_to='element_4'>0.14999999999999999 0 0 0 0 0</pose>
      <parent>element_4</parent>
      <child>element_5</child>
      <axis>
        <xyz>0 1 1</xyz>
        <limit>
          <lower>-inf</lower>
          <upper>inf</upper>
        </limit>
        <dynamics>
          <damping>10</damping>
          <friction>0</friction>
          <spring_reference>0</spring_reference>
          <spring_stiffness>0</spring_stiffness>
        </dynamics>
      </axis>
    </joint>
    <link name='element_5'>
      <pose relative_to='joint_4_to_5'>0 0 0 0 0 0</pose>
      <inertial>
        <pose>0.074999999999999997 0 0 0 1.5707963267948966 0</pose>
        <mass>0.01</mass>
        <inertia>
          <ixx>1.9000000000000001e-05</ixx>
          <ixy>0</ixy>
          <ixz>0</ixz>
          <iyy>1.9000000000000001e-05</iyy>
          <iyz>0</iyz>
          <izz>5.0000000000000008e-07</izz>
        </inertia>
      </inertial>
      <collision name='element_5_collision'>
        <pose>0.074999999999999997 0 0 0 1.5707963267948966 0</pose>
        <geometry>
          <cylinder>
            <length>0.0001</length>
            <radius>0.0001</radius>
          </cylinder>
        </geometry>
      </collision>
      <visual name='element_5_visual'>
        <pose>0.074999999999999997 0 0 0 1.5707963267948966 0</pose>
        <geometry>
          <cylinder>
            <length>0.14999999999999999</length>
            <radius>0.01</radius>
          </cylinder>
        </geometry>
      </visual>
    </link>
    <joint name='joint_5_to_6' type='ball'>
      <pose relative_to='element_5'>0.14999999999999999 0 0 0 0 0</pose>
      <parent>element_5</parent>
      <child>element_6</child>
      <axis>
        <xyz>0 1 1</xyz>
        <limit>
          <lower>-inf</lower>
          <upper>inf</upper>
        </limit>
        <dynamics>
          <damping>10</damping>
          <friction>0</friction>
          <spring_reference>0</spring_reference>
          <spring_stiffness>0</spring_stiffness>
        </dynamics>
      </axis>
    </joint>
    <link name='element_6'>
      <pose relative_to='joint_5_to_6'>0 0 0 0 0 0</pose>
      <inertial>
        <pose>0.074999999999999997 0 0 0 1.5707963267948966 0</pose>
        <mass>0.01</mass>
        <inertia>
          <ixx>1.9000000000000001e-05</ixx>
          <ixy>0</ixy>
          <ixz>0</ixz>
          <iyy>1.9000000000000001e-05</iyy>
          <iyz>0</iyz>
          <izz>5.0000000000000008e-07</izz>
        </inertia>
      </inertial>
      <collision name='element_6_collision'>
        <pose>0.074999999999999997 0 0 0 1.5707963267948966 0</pose>
        <geometry>
          <cylinder>
            <length>0.0001</length>
            <radius>0.0001</radius>
          </cylinder>
        </geometry>
      </collision>
      <visual name='element_6_visual'>
        <pose>0.074999999999999997 0 0 0 1.5707963267948966 0</pose>
        <geometry>
          <cylinder>
            <length>0.14999999999999999</length>
            <radius>0.01</radius>
          </cylinder>
        </geometry>
      </visual>
    </link>
    <joint name='joint_6_to_7' type='ball'>
      <pose relative_to='element_6'>0.14999999999999999 0 0 0 0 0</pose>
      <parent>element_6</parent>
      <child>element_7</child>
      <axis>
        <xyz>0 1 1</xyz>
        <limit>
          <lower>-inf</lower>
          <upper>inf</upper>
        </limit>
        <dynamics>
          <damping>10</damping>
          <friction>0</friction>
          <spring_reference>0</spring_reference>
          <spring_stiffness>0</spring_stiffness>
        </dynamics>
      </axis>
    </joint>
    <link name='element_7'>
      <pose relative_to='joint_6_to_7'>0 0 0 0 0 0</pose>
      <inertial>
        <pose>0.074999999999999997 0 0 0 1.5707963267948966 0</pose>
        <mass>0.01</mass>
        <inertia>
          <ixx>1.9000000000000001e-05</ixx>
          <ixy>0</ixy>
          <ixz>0</ixz>
          <iyy>1.9000000000000001e-05</iyy>
          <iyz>0</iyz>
          <izz>5.0000000000000008e-07</izz>
        </inertia>
      </inertial>
      <collision name='element_7_collision'>
        <pose>0.074999999999999997 0 0 0 1.5707963267948966 0</pose>
        <geometry>
          <cylinder>
            <length>0.0001</length>
            <radius>0.0001</radius>
          </cylinder>
        </geometry>
      </collision>
      <visual name='element_7_visual'>
        <pose>0.074999999999999997 0 0 0 1.5707963267948966 0</pose>
        <geometry>
          <cylinder>
            <length>0.14999999999999999</length>
            <radius>0.01</radius>
          </cylinder>
        </geometry>
      </visual>
    </link>
    <joint name='joint_7_to_8' type='ball'>
      <pose relative_to='element_7'>0.14999999999999999 0 0 0 0 0</pose>
      <parent>element_7</parent>
      <child>element_8</child>
      <axis>
        <xyz>0 1 1</xyz>
        <limit>
          <lower>-inf</lower>
          <upper>inf</upper>
        </limit>
        <dynamics>
          <damping>10</damping>
          <friction>0</friction>
          <spring_reference>0</spring_reference>
          <spring_stiffness>0</spring_stiffness>
        </dynamics>
      </axis>
    </joint>
    <link name='element_8'>
      <pose relative_to='joint_7_to_8'>0 0 0 0 0 0</pose>
      <inertial>
        <pose>0.074999999999999997 0 0 0 1.5707963267948966 0</pose>
        <mass>0.01</mass>
        <inertia>
          <ixx>1.9000000000000001e-05</ixx>
          <ixy>0</ixy>
          <ixz>0</ixz>
          <iyy>1.9000000000000001e-05</iyy>
          <iyz>0</iyz>
          <izz>5.0000000000000008e-07</izz>
        </inertia>
      </inertial>
      <collision name='element_8_collision'>
        <pose>0.074999999999999997 0 0 0 1.5707963267948966 0</pose>
        <geometry>
          <cylinder>
            <length>0.0001</length>
            <radius>0.0001</radius>
          </cylinder>
        </geometry>
      </collision>
      <visual name='element_8_visual'>
        <pose>0.074999999999999997 0 0 0 1.5707963267948966 0</pose>
        <geometry>
          <cylinder>
            <length>0.14999999999999999</length>
            <radius>0.01</radius>
          </cylinder>
        </geometry>
      </visual>
    </link>
    <joint name='joint_8_to_9' type='ball'>
      <pose relative_to='element_8'>0.14999999999999999 0 0 0 0 0</pose>
      <parent>element_8</parent>
      <child>element_9</child>
      <axis>
        <xyz>0 1 1</xyz>
        <limit>
          <lower>-inf</lower>
          <upper>inf</upper>
        </limit>
        <dynamics>
          <damping>10</damping>
          <friction>0</friction>
          <spring_reference>0</spring_reference>
          <spring_stiffness>0</spring_stiffness>
        </dynamics>
      </axis>
    </joint>
    <link name='element_9'>
      <pose relative_to='joint_8_to_9'>0 0 0 0 0 0</pose>
      <inertial>
        <pose>0.074999999999999997 0 0 0 1.5707963267948966 0</pose>
        <mass>0.01</mass>
        <inertia>
          <ixx>1.9000000000000001e-05</ixx>
          <ixy>0</ixy>
          <ixz>0</ixz>
          <iyy>1.9000000000000001e-05</iyy>
          <iyz>0</iyz>
          <izz>5.0000000000000008e-07</izz>
        </inertia>
      </inertial>
      <collision name='element_9_collision'>
        <pose>0.074999999999999997 0 0 0 1.5707963267948966 0</pose>
        <geometry>
          <cylinder>
            <length>0.0001</length>
            <radius>0.0001</radius>
          </cylinder>
        </geometry>
      </collision>
      <visual name='element_9_visual'>
        <pose>0.074999999999999997 0 0 0 1.5707963267948966 0</pose>
        <geometry>
          <cylinder>
            <length>0.14999999999999999</length>
            <radius>0.01</radius>
          </cylinder>
        </geometry>
      </visual>
    </link>
    <joint name='joint_9_to_10' type='ball'>
      <pose relative_to='element_9'>0.14999999999999999 0 0 0 0 0</pose>
      <parent>element_9</parent>
      <child>element_10</child>
      <axis>
        <xyz>0 1 1</xyz>
        <limit>
          <lower>-inf</lower>
          <upper>inf</upper>
        </limit>
        <dynamics>
          <damping>10</damping>
          <friction>0</friction>
          <spring_reference>0</spring_reference>
          <spring_stiffness>0</spring_stiffness>
        </dynamics>
      </axis>
    </joint>
    <link name='element_10'>
      <pose relative_to='joint_9_to_10'>0 0 0 0 0 0</pose>
      <inertial>
        <pose>0.074999999999999997 0 0 0 1.5707963267948966 0</pose>
        <mass>0.01</mass>
        <inertia>
          <ixx>1.9000000000000001e-05</ixx>
          <ixy>0</ixy>
          <ixz>0</ixz>
          <iyy>1.9000000000000001e-05</iyy>
          <iyz>0</iyz>
          <izz>5.0000000000000008e-07</izz>
        </inertia>
      </inertial>
      <collision name='element_10_collision'>
        <pose>0.074999999999999997 0 0 0 1.5707963267948966 0</pose>
        <geometry>
          <cylinder>
            <length>0.0001</length>
            <radius>0.0001</radius>
          </cylinder>
        </geometry>
      </collision>
      <visual name='element_10_visual'>
        <pose>0.074999999999999997 0 0 0 1.5707963267948966 0</pose>
        <geometry>
          <cylinder>
            <length>0.14999999999999999</length>
            <radius>0.01</radius>
          </cylinder>
        </geometry>
      </visual>
    </link>
    <joint name='joint_10_to_11' type='ball'>
      <pose relative_to='element_10'>0.14999999999999999 0 0 0 0 0</pose>
      <parent>element_10</parent>
      <child>element_11</child>
      <axis>
        <xyz>0 1 1</xyz>
        <limit>
          <lower>-inf</lower>
          <upper>inf</upper>
        </limit>
        <dynamics>
          <spring_reference>0</spring_reference>
          <spring_stiffness>0</spring_stiffness>
        </dynamics>
      </axis>
    </joint>
    <link name='element_11'>
      <pose relative_to='joint_10_to_11'>0 0 0 0 0 0</pose>
      <inertial>
        <pose>0.0050000000000000001 0 0 0 1.5707963267948966 0</pose>
        <mass>0.00066666666666666664</mass>
        <inertia>
          <ixx>2.222222222222222e-08</ixx>
          <ixy>0</ixy>
          <ixz>0</ixz>
          <iyy>2.222222222222222e-08</iyy>
          <iyz>0</iyz>
          <izz>3.3333333333333327e-08</izz>
        </inertia>
      </inertial>
      <collision name='element_11_collision'>
        <pose>0.0050000000000000001 0 0 0 1.5707963267948966 0</pose>
        <geometry>
          <cylinder>
            <length>0.0001</length>
            <radius>0.0001</radius>
          </cylinder>
        </geometry>
      </collision>
      <visual name='element_11_visual'>
        <pose>0.0050000000000000001 0 0 0 1.5707963267948966 0</pose>
        <geometry>
          <cylinder>
            <length>0.01</length>
            <radius>0.01</radius>
          </cylinder>
        </geometry>
      </visual>
    </link>
  </model>
</sdf>
